Workbook

Sheet INFO
A1: Sectors | D1: Regions | G1: Variables
A2: AGR01 | B2: Agriculture | D2: AUT | E2: Austria | G2: GDP | H2: Macroeconomic Aggregates - GDP in b$ 2017
A3: ENE01 | B3: Coal | D3: BEL | E3: Belgium | G3: GCVTOT | H3: Macro Results - Government Consumption - b$ 2017
A4: ENE02 | B4: Crude Oil | D4: BGR | E4: Bulgaria | G4: INVVCO | H4: Macro Results - Investment - b$ 2017
A5: ENE03 | B5: Oil | D5: HRV | E5: Croatia | G5: RHCDTOTV | H5: Macro Results - Household Consumption - b$ 2017
A6: ENE04 | B6: Gas | D6: CYP | E6: Cyprus | G6: POP | H6: Macro Results - Population - in million of persons
A7: ENE05 | B7: Power Supply | D7: CZE | E7: Czechia
A8: IND01 | B8: Non-metallic minerals mining | D8: DNK | E8: Denmark | G8: PROD | H8: Sectoral Results - Production - b$ 2017
A9: IND02 | B9: Mining of iron ores | D9: EST | E9: Estonia | G9: EXPORTS | H9: Sectoral Results - Exports - b$ 2017
A10: IND03 | B10: Mining of bauxite ores | D10: FIN | E10: Finland | G10: IMPORTS | H10: Sectoral Results - Imports - b$ 2017 (incl. transport margins and duties)
A11: IND04 | B11: Mining of copper ores | D11: FRA | E11: France | G11: DEMAND | H11: Sectoral Results - Demand - b$ 2017
A12: IND05 | B12: Mining of other ores | D12: DEU | E12: Germany
A13: IND06 | B13: Potassium fertilizer | D13: GRC | E13: Greece
A14: IND07 | B14: Nitrogen fertilizer | D14: HUN | E14: Hungary
A15: IND08 | B15: Phosphorus fertilizer | D15: IRL | E15: Ireland
A16: IND09 | B16: Other chemicals | D16: ITA | E16: Italy
A17: IND10 | B17: Basic pharmaceutical products | D17: LVA | E17: Latvia
A18: IND11 | B18: Rubber products | D18: LTU | E18: Lithuania
A19: IND12 | B19: Plastic products-primary | D19: LUX | E19: Luxembourg
A20: IND13 | B20: Plastic products-secondary | D20: MLT | E20: Malta
A21: IND14 | B21: Recycling-plastics | D21: NLD | E21: Netherlands
A22: IND15 | B22: Cement | D22: POL | E22: Poland
A23: IND16 | B23: Other mineral products | D23: PRT | E23: Portugal
... A29: IND22 | B29: Aluminum-secondary | D29: ROW | E29: Rest of the World
A30: IND23 | B30: Recycling-aluminum
A31: IND24 | B31: Copper-primary
A32: IND25 | B32: Copper-secondary
A33: IND26 | B33: Recycling-copper
A34: IND27 | B34: Other metals-primary
A35: IND28 | B35: Other metals-secondary
A36: IND29 | B36: Recycling-other metals
A37: IND30 | B37: Non-ferrous metals casting
A38: IND31 | B38: Metal products
A39: IND32 | B39: Paper products, publishing
A40: IND33 | B40: Equipment Goods
A41: IND34 | B41: Consumer Goods Industries
... A46: SRV02 | B46: Non-Market Services

Sheet MACRO_BASE
D2: 2017 | E2: 2020 | F2: 2025 | G2: 2030 | H2: 2035 | I2: 2040 | J2: 2045 | K2: 2050
B3: GDP | C3: AUT | D3: 417.26098 | E3: 442.97251 | F3: 467.51373 | G3: 514.17976 | H3: 549.07275 | I3: 583.97345 | J3: 619.20172 | K3: 653.14256
B4: GDP | C4: BEL | D4: 502.76157 | E4: 556.64599 | F4: 580.98964 | G4: 627.95748 | H4: 669.13728 | I4: 707.58632 | J4: 744.43285 | K4: 781.70292
B5: GDP | C5: BGR | D5: 59.198664 | E5: 63.359287 | F5: 74.739607 | G5: 86.000885 | H5: 96.263453 | I5: 105.3435 | J5: 113.7408 | K5: 121.9986
B6: GDP | C6: HRV | D6: 56.2129 | E6: 58.233848 | F6: 74.856953 | G6: 85.024125 | H6: 92.062215 | I6: 96.607084 | J6: 99.597809 | K6: 101.65242
B7: GDP | C7: CYP | D7: 22.870805 | E7: 23.497388 | F7: 30.976297 | G7: 35.706277 | H7: 40.475549 | I7: 45.132086 | J7: 49.771921 | K7: 54.454125
B8: GDP | C8: CZE | D8: 218.62702 | E8: 234.16188 | F8: 251.42007 | G8: 273.22019 | H8: 293.9978 | I8: 314.63607 | J8: 334.84415 | K8: 354.73245
B9: GDP | C9: DNK | D9: 332.11886 | E9: 348.32493 | F9: 395.02289 | G9: 422.26203 | H9: 449.11787 | I9: 476.83528 | J9: 507.04848 | K9: 538.95148
B10: GDP | C10: EST | D10: 26.923978 | E10: 29.562598 | F10: 31.579197 | G10: 37.305323 | H10: 41.024955 | I10: 43.75839 | J10: 45.632144 | K10: 47.083976
B11: GDP | C11: FIN | D11: 256.96811 | E11: 268.79947 | F11: 286.37282 | G11: 307.90757 | H11: 326.05492 | I11: 344.73241 | J11: 363.86295 | K11: 383.70497
B12: GDP | C12: FRA | D12: 2640.2479 | E12: 2749.9288 | F12: 2944.768 | G12: 3186.2102 | H12: 3398.5315 | I12: 3614.733 | J12: 3835.3285 | K12: 4064.7278
B13: GDP | C13: DEU | D13: 3690.8157 | E13: 3870.7816 | F13: 4015.3022 | G13: 4226.205 | H13: 4449.7564 | I13: 4712.3095 | J13: 4991.6061 | K13: 5261.5412
B14: GDP | C14: GRC | D14: 199.8516 | E14: 198.93647 | F14: 237.70066 | G14: 263.45536 | H14: 283.87957 | I14: 306.84822 | J14: 329.78166 | K14: 352.2186
... B142: POP | C142: ROW | D142: 7066.0704 | E142: 7315.8962 | F142: 7659.6725 | G142: 8005.0339 | H142: 8325.6818 | I142: 8619.4883 | J142: 8880.1327 | K142: 9102.8315

Sheet SECTOR_BASE
E2: 2017 | F2: 2020 | G2: 2025 | H2: 2030 | I2: 2035 | J2: 2040 | K2: 2045 | L2: 2050
B3: PROD | C3: AGR01 | D3: AUT | E3: 11.943814 | F3: 12.655291 | G3: 13.914252 | H3: 15.039233 | I3: 16.111904 | J3: 17.215889 | K3: 18.307884 | L3: 19.396029
B4: PROD | C4: AGR01 | D4: BEL | E4: 11.867644 | F4: 13.384678 | G4: 15.131091 | H4: 17.046079 | I4: 18.700752 | J4: 20.290672 | K4: 21.851333 | L4: 23.424009
B5: PROD | C5: AGR01 | D5: BGR | E5: 5.6849417 | F5: 5.9629062 | G5: 6.7647351 | H5: 7.4891593 | I5: 8.2919125 | J5: 9.0948395 | K5: 9.8523426 | L5: 10.543797
B6: PROD | C6: AGR01 | D6: HRV | E6: 3.524676 | F6: 3.466756 | G6: 4.1666172 | H6: 4.519888 | I6: 4.7831788 | J6: 4.957534 | K6: 5.0674202 | L6: 5.135374
B7: PROD | C7: AGR01 | D7: CYP | E7: 0.95627791 | F7: 0.95130489 | G7: 1.1591414 | H7: 1.285081 | I7: 1.4180683 | J7: 1.5564956 | K7: 1.6995304 | L7: 1.8473271
B8: PROD | C8: AGR01 | D8: CZE | E8: 8.7010166 | F8: 9.2380483 | G8: 10.64278 | H8: 11.790691 | I8: 12.899226 | J8: 13.971537 | K8: 15.035353 | L8: 16.105139
B9: PROD | C9: AGR01 | D9: DNK | E9: 12.63339 | F9: 13.004103 | G9: 15.210733 | H9: 16.600612 | I9: 17.906173 | J9: 19.239121 | K9: 20.657275 | L9: 22.184695
B10: PROD | C10: AGR01 | D10: EST | E10: 1.6875297 | F10: 1.9249808 | G10: 2.2440892 | H10: 2.6107999 | I10: 2.940827 | J10: 3.2295978 | K10: 3.4741747 | L10: 3.6848018
B11: PROD | C11: AGR01 | D11: FIN | E11: 10.941716 | F11: 11.543592 | G11: 12.646665 | H11: 13.628143 | I11: 14.583177 | J11: 15.505125 | K11: 16.422001 | L11: 17.362625
B12: PROD | C12: AGR01 | D12: FRA | E12: 76.553209 | F12: 79.219189 | G12: 87.00756 | H12: 93.59726 | I12: 100.15911 | J12: 106.7845 | K12: 113.5321 | L12: 120.47618
B13: PROD | C13: AGR01 | D13: DEU | E13: 64.794826 | F13: 67.351723 | G13: 72.033566 | H13: 76.125996 | I13: 79.779941 | J13: 83.474381 | K13: 87.292951 | L13: 91.163343
B14: PROD | C14: AGR01 | D14: GRC | E14: 22.220988 | F14: 20.825087 | G14: 22.796151 | H14: 23.855344 | I14: 24.787394 | J14: 25.82106 | K14: 26.883414 | L14: 27.950384
... B199: PROD | C199: IND02 | D199: AUT | E199: 0.26673722 | F199: 0.2915694 | G199: 0.2984821 | H199: 0.3129707 | I199: 0.32612888 | J199: 0.34794884 | K199: 0.36914847 | L199: 0.38905911
B200: PROD | C200: IND02 | D200: BEL | E200: 6.8625745e-15
B201: PROD | C201: IND02 | D201: BGR | E201: 0.0001203172 | F201: 0.00012960543 | G201: 0.00015320685 | H201: 0.00017562084 | I201: 0.00019702413 | J201: 0.00021670277 | K201: 0.00023487335 | L201: 0.00025238183
B202: PROD | C202: IND02 | D202: HRV | E202: 4.3792288e-15
B203: PROD | C203: IND02 | D203: CYP | E203: 0.00062859867 | F203: 0.00063707856 | G203: 0.00071366939 | H203: 0.00074744543 | I203: 0.00078837108 | J203: 0.000835499 | K203: 0.00088347833 | L203: 0.00093198972
B204: PROD | C204: IND02 | D204: CZE | E204: 3.1416623e-15
B205: PROD | C205: IND02 | D205: DNK | E205: 1.1464409e-14 | F205: 1.2008501e-14 | G205: 1.3135175e-14 | H205: 1.3108586e-14 | I205: 1.3181082e-14 | J205: 1.3193197e-14 | K205: 1.3394283e-14 | L205: 1.3573011e-14
B206: PROD | C206: IND02 | D206: EST | E206: 0.0011027514 | F206: 0.0011099329 | G206: 0.0010842532 | H206: 0.00094490098 | I206: 0.00085892587 | J206: 0.00079848787 | K206: 0.00075035827 | L206: 0.00070577219
B207: PROD | C207: IND02 | D207: FIN | E207: 4.1400382e-15
B208: PROD | C208: IND02 | D208: FRA | E208: 3.5522718e-15
B209: PROD | C209: IND02 | D209: DEU | E209: 6.0971607e-15
B210: PROD | C210: IND02 | D210: GRC | E210: 0.12277949 | F210: 0.12615719 | G210: 0.16522109 | H210: 0.18998749 | I210: 0.21125075 | J210: 0.23550903 | K210: 0.2596718 | L210: 0.28326327
B211: PROD | C211: IND02 | D211: HUN | E211: 2.7997785e-15
B212: PROD | C212: IND02 | D212: IRL | E212: 0.00032003812 | F212: 0.0003426925 | G212: 0.00038892153 | H212: 0.00039071169 | I212: 0.0004027438 | J212: 0.00042322497 | K212: 0.00045103556 | L212: 0.00047956326
B213: PROD | C213: IND02 | D213: ITA | E213: 5.6936341e-15
B214: PROD | C214: IND02 | D214: LVA | E214: 0.0011365303 | F214: 0.0013274124 | G214: 0.0014184472 | H214: 0.0015348156 | I214: 0.0016311605 | J214: 0.0017048266 | K214: 0.0017458472 | L214: 0.0017717786
B215: PROD | C215: IND02 | D215: LTU | E215: 0.0017745435 | F215: 0.0020788956 | G215: 0.0023303734 | H215: 0.0025910472 | I215: 0.0028227033 | J215: 0.00299504 | K215: 0.0030940463 | L215: 0.0031172816
B216: PROD | C216: IND02 | D216: LUX | E216: 0.00057439647 | F216: 0.00071775907 | G216: 0.00071090967 | H216: 0.00079414739 | I216: 0.0008507753 | J216: 0.00089147287 | K216: 0.00091571601 | L216: 0.00093120275
B217: PROD | C217: IND02 | D217: MLT | E217: 0.00058422113 | F217: 0.00070217922 | G217: 0.00089944952 | H217: 0.0010674309 | I217: 0.0012372779 | J217: 0.001398664 | K217: 0.0015407442 | L217: 0.0016642229
B218: PROD | C218: IND02 | D218: NLD | E218: 9.1154626e-15 | F218: 9.6009688e-15 | G218: 9.8541597e-15 | H218: 1.9949681e-14 | I218: 2.1197852e-14 | J218: 2.2244251e-14 | K218: 2.3251927e-14 | L218: 2.4158148e-14
B219: PROD | C219: IND02 | D219: POL | E219: 3.7645875e-15
B220: PROD | C220: IND02 | D220: PRT | E220: 3.9596e-15
B221: PROD | C221: IND02 | D221: ROU | E221: 1.7588236e-14 | F221: 2.0921665e-14 | G221: 2.5192979e-14 | H221: 2.7892899e-14 | I221: 3.0101857e-14 | J221: 3.1639698e-14 | K221: 3.2460116e-14 | L221: 3.2771422e-14
B222: PROD | C222: IND02 | D222: SVK | E222: 9.4635051e-14 | F222: 1.0476441e-13 | G222: 1.1467353e-13 | H222: 1.2548774e-13 | I222: 1.3630961e-13 | J222: 1.469393e-13 | K222: 1.5592661e-13 | L222: 1.6393925e-13
B223: PROD | C223: IND02 | D223: SVN | E223: 5.4730781e-14 | F223: 7.1175259e-14 | H223: 9.1541445e-14 | I223: 9.8248557e-14 | J223: 8.4821245e-14 | K223: 8.8260465e-14 | L223: 9.1727369e-14
B224: PROD | C224: IND02 | D224: ESP | E224: 1.7419146e-15
B225: PROD | C225: IND02 | D225: SWE | E225: 2.9639869 | F225: 3.2625579 | G225: 3.4971057 | H225: 3.8057695 | I225: 4.1372419 | J225: 4.4866277 | K225: 4.8405389 | L225: 5.1945888
...

Sheet MACRO_CHM_REC
D2: 2017 | E2: 2020 | F2: 2025 | G2: 2030 | H2: 2035 | I2: 2040 | J2: 2045 | K2: 2050
B3: GDP | C3: AUT | D3: 417.26098 | E3: 442.97251 | F3: 467.51373 | G3: 514.17192 | H3: 549.05885 | I3: 583.95396 | J3: 619.17711 | K3: 653.1133
B4: GDP | C4: BEL | D4: 502.76157 | E4: 556.64599 | F4: 580.98964 | G4: 627.93945 | H4: 669.11969 | I4: 707.56859 | J4: 744.4144 | K4: 781.68309
B5: GDP | C5: BGR | D5: 59.198664 | E5: 63.359287 | F5: 74.739607 | G5: 86.000608 | H5: 96.262083 | I5: 105.34113 | J5: 113.73752 | K5: 121.99447
B6: GDP | C6: HRV | D6: 56.2129 | E6: 58.233848 | F6: 74.856953 | G6: 85.023822 | H6: 92.061134 | I6: 96.605363 | J6: 99.595582 | K6: 101.6498
B7: GDP | C7: CYP | D7: 22.870805 | E7: 23.497388 | F7: 30.976297 | G7: 35.706272 | H7: 40.47533 | I7: 45.13166 | J7: 49.771306 | K7: 54.45334
B8: GDP | C8: CZE | D8: 218.62702 | E8: 234.16188 | F8: 251.42007 | G8: 273.21507 | H8: 293.98851 | I8: 314.62308 | J8: 334.82781 | K8: 354.71302
B9: GDP | C9: DNK | D9: 332.11886 | E9: 348.32493 | F9: 395.02289 | G9: 422.25982 | H9: 449.11312 | I9: 476.82843 | J9: 507.03981 | K9: 538.9412
B10: GDP | C10: EST | D10: 26.923978 | E10: 29.562598 | F10: 31.579197 | G10: 37.30524 | H10: 41.0245 | I10: 43.757618 | J10: 45.631115 | K10: 47.082738
B11: GDP | C11: FIN | D11: 256.96811 | E11: 268.79947 | F11: 286.37282 | G11: 307.90582 | H11: 326.05129 | I11: 344.72705 | J11: 363.85597 | K11: 383.69648
B12: GDP | C12: FRA | D12: 2640.2479 | E12: 2749.9288 | F12: 2944.768 | G12: 3186.1864 | H12: 3398.4944 | I12: 3614.6826 | J12: 3835.2648 | K12: 4064.6507
B13: GDP | C13: DEU | D13: 3690.8157 | E13: 3870.7816 | F13: 4015.3022 | G13: 4225.4372 | H13: 4448.8179 | I13: 4711.2006 | J13: 4990.3428 | K13: 5260.1516
B14: GDP | C14: GRC | D14: 199.8516 | E14: 198.93647 | F14: 237.70066 | G14: 263.45486 | H14: 283.87755 | I14: 306.84478 | J14: 329.77689 | K14: 352.21261
... B142: POP | C142: ROW | D142: 7066.0704 | E142: 7315.8962 | F142: 7659.6725 | G142: 8005.0339 | H142: 8325.6818 | I142: 8619.4883 | J142: 8880.1327 | K142: 9102.8315

Sheet SECTOR_CHM_REC
E2: 2017 | F2: 2020 | G2: 2025 | H2: 2030 | I2: 2035 | J2: 2040 | K2: 2045 | L2: 2050
B3: PROD | C3: AGR01 | D3: AUT | E3: 11.943814 | F3: 12.655291 | G3: 13.914252 | H3: 15.040243 | I3: 16.11256 | J3: 17.216189 | K3: 18.307846 | L3: 19.395686
B4: PROD | C4: AGR01 | D4: BEL | E4: 11.867644 | F4: 13.384678 | G4: 15.131091 | H4: 17.050067 | I4: 18.70446 | J4: 20.293997 | K4: 21.854244 | L4: 23.426529
B5: PROD | C5: AGR01 | D5: BGR | E5: 5.6849417 | F5: 5.9629062 | G5: 6.7647351 | H5: 7.4888971 | I5: 8.2914683 | J5: 9.094209 | K5: 9.8515419 | L5: 10.542856
B6: PROD | C6: AGR01 | D6: HRV | E6: 3.524676 | F6: 3.466756 | G6: 4.1666172 | H6: 4.5198174 | I6: 4.7830681 | J6: 4.9573943 | K6: 5.0672617 | L6: 5.1352042
B7: PROD | C7: AGR01 | D7: CYP | E7: 0.95627791 | F7: 0.95130489 | G7: 1.1591414 | H7: 1.2850595 | I7: 1.4180355 | J7: 1.5564528 | K7: 1.6994791 | L7: 1.8472682
B8: PROD | C8: AGR01 | D8: CZE | E8: 8.7010166 | F8: 9.2380483 | G8: 10.64278 | H8: 11.79173 | I8: 12.900015 | J8: 13.972055 | K8: 15.035608 | L8: 16.105158
B9: PROD | C9: AGR01 | D9: DNK | E9: 12.63339 | F9: 13.004103 | G9: 15.210733 | H9: 16.60098 | I9: 17.9063 | J9: 19.238972 | K9: 20.656851 | L9: 22.184017
B10: PROD | C10: AGR01 | D10: EST | E10: 1.6875297 | F10: 1.9249808 | G10: 2.2440892 | H10: 2.6107441 | I10: 2.9407184 | J10: 3.2294415 | K10: 3.4739787 | L10: 3.684574
B11: PROD | C11: AGR01 | D11: FIN | E11: 10.941716 | F11: 11.543592 | G11: 12.646665 | H11: 13.628109 | I11: 14.582945 | J11: 15.504697 | K11: 16.42139 | L11: 17.361849
B12: PROD | C12: AGR01 | D12: FRA | E12: 76.553209 | F12: 79.219189 | G12: 87.00756 | H12: 93.599608 | I12: 100.16046 | J12: 106.78475 | K12: 113.53127 | L12: 120.47436
B13: PROD | C13: AGR01 | D13: DEU | E13: 64.794826 | F13: 67.351723 | G13: 72.033566 | H13: 76.052114 | I13: 79.704078 | J13: 83.398758 | K13: 87.218527 | L13: 91.090217
B14: PROD | C14: AGR01 | D14: GRC | E14: 22.220988 | F14: 20.825087 | G14: 22.796151 | H14: 23.855231 | I14: 24.787079 | J14: 25.820553 | K14: 26.882735 | L14: 27.949553
... B199: PROD | C199: IND02 | D199: AUT | E199: 0.26673722 | F199: 0.2915694 | G199: 0.2984821 | H199: 0.31294045 | I199: 0.32608789 | J199: 0.34789826 | K199: 0.36908967 | L199: 0.38899317
B200: PROD | C200: IND02 | D200: BEL | E200: 6.8625745e-15
B201: PROD | C201: IND02 | D201: BGR | E201: 0.0001203172 | F201: 0.00012960543 | G201: 0.00015320685 | H201: 0.00017559686 | I201: 0.00019699749 | J201: 0.00021667476 | K201: 0.00023484472 | L201: 0.00025235272
B202: PROD | C202: IND02 | D202: HRV | E202: 4.3792288e-15
B203: PROD | C203: IND02 | D203: CYP | E203: 0.00062859867 | F203: 0.00063707856 | G203: 0.00071366939 | H203: 0.00074752469 | I203: 0.00078844089 | J203: 0.00083556291 | K203: 0.0008835376 | L203: 0.0009320442
B204: PROD | C204: IND02 | D204: CZE | E204: 3.1416623e-15
B205: PROD | C205: IND02 | D205: DNK | E205: 1.1464409e-14 | F205: 1.2008501e-14 | G205: 1.3135175e-14 | H205: 1.3175245e-14 | I205: 1.3120573e-14 | J205: 1.3193463e-14 | K205: 1.3393851e-14 | L205: 1.3572972e-14
B206: PROD | C206: IND02 | D206: EST | E206: 0.0011027514 | F206: 0.0011099329 | G206: 0.0010842532 | H206: 0.0009449535 | I206: 0.00085895426 | J206: 0.00079850008 | K206: 0.00075035931 | L206: 0.00070576522
B207: PROD | C207: IND02 | D207: FIN | E207: 4.1400382e-15
B208: PROD | C208: IND02 | D208: FRA | E208: 3.5522718e-15
B209: PROD | C209: IND02 | D209: DEU | E209: 6.0971607e-15
B210: PROD | C210: IND02 | D210: GRC | E210: 0.12277949 | F210: 0.12615719 | G210: 0.16522109 | H210: 0.18998703 | I210: 0.21124919 | J210: 0.23550638 | K210: 0.25966806 | L210: 0.28325846
B211: PROD | C211: IND02 | D211: HUN | E211: 2.7997785e-15
B212: PROD | C212: IND02 | D212: IRL | E212: 0.00032003812 | F212: 0.0003426925 | G212: 0.00038892153 | H212: 0.00039073676 | I212: 0.00040276228 | J212: 0.00042323921 | K212: 0.00045104669 | L212: 0.00047957171
B213: PROD | C213: IND02 | D213: ITA | E213: 5.6936341e-15
B214: PROD | C214: IND02 | D214: LVA | E214: 0.0011365303 | F214: 0.0013274124 | G214: 0.0014184472 | H214: 0.0015349922 | I214: 0.0016312811 | J214: 0.0017048943 | K214: 0.0017458676 | L214: 0.0017717595
B215: PROD | C215: IND02 | D215: LTU | E215: 0.0017745435 | F215: 0.0020788956 | G215: 0.0023303734 | H215: 0.0025913819 | I215: 0.0028229208 | J215: 0.0029951314 | K215: 0.0030940195 | L215: 0.0031171571
B216: PROD | C216: IND02 | D216: LUX | E216: 0.00057439647 | F216: 0.00071775907 | G216: 0.00071090967 | H216: 0.00079405309 | I216: 0.00085066057 | J216: 0.00089135094 | K216: 0.00091559523 | L216: 0.00093108931
B217: PROD | C217: IND02 | D217: MLT | E217: 0.00058422113 | F217: 0.00070217922 | G217: 0.00089944952 | H217: 0.0010674128 | I217: 0.0012372407 | J217: 0.0013986094 | K217: 0.0015406738 | L217: 0.0016641383
B218: PROD | C218: IND02 | D218: NLD | E218: 9.1154626e-15 | F218: 9.6009688e-15 | G218: 9.8541597e-15 | H218: 2.0132988e-14 | I218: 2.1003054e-14 | J218: 2.2058496e-14 | K218: 2.3255465e-14 | L218: 2.4157112e-14
B219: PROD | C219: IND02 | D219: POL | E219: 3.7645875e-15
B220: PROD | C220: IND02 | D220: PRT | E220: 3.9596e-15
B221: PROD | C221: IND02 | D221: ROU | E221: 1.7588236e-14 | F221: 2.0921665e-14 | G221: 2.5192979e-14 | H221: 2.7896049e-14 | I221: 3.009829e-14 | J221: 3.1629881e-14 | K221: 3.2458331e-14 | L221: 3.2774406e-14
B222: PROD | C222: IND02 | D222: SVK | E222: 9.4635051e-14 | F222: 1.0476441e-13 | G222: 1.1467353e-13 | H222: 1.2550101e-13 | I222: 1.3631541e-13 | J222: 1.469612e-13 | K222: 1.558879e-13 | L222: 1.6393294e-13
B223: PROD | C223: IND02 | D223: SVN | E223: 5.4730781e-14 | F223: 7.1175259e-14 | H223: 9.1522374e-14 | I223: 9.8226826e-14 | J223: 8.4800121e-14 | K223: 8.8239493e-14 | L223: 9.1705298e-14
B224: PROD | C224: IND02 | D224: ESP | E224: 1.7419146e-15
B225: PROD | C225: IND02 | D225: SWE | E225: 2.9639869 | F225: 3.2625579 | G225: 3.4971057 | H225: 3.805201 | I225: 4.1365934 | J225: 4.4859135 | K225: 4.8397697 | L225: 5.1937727
...

Sheet MACRO_CHM_REC_INV
D2: 2017 | E2: 2020 | F2: 2025 | G2: 2030 | H2: 2035 | I2: 2040 | J2: 2045 | K2: 2050
B3: GDP | C3: AUT | D3: 417.26098 | E3: 442.97251 | F3: 467.51347 | G3: 514.16792 | H3: 549.05705 | I3: 583.95411 | J3: 619.17899 | K3: 653.1167
B4: GDP | C4: BEL | D4: 502.76157 | E4: 556.64599 | F4: 580.99139 | G4: 627.93377 | H4: 669.11689 | I4: 707.5682 | J4: 744.41606 | K4: 781.6865
B5: GDP | C5: BGR | D5: 59.198664 | E5: 63.359287 | F5: 74.739757 | G5: 85.999753 | H5: 96.261586 | I5: 105.34096 | J5: 113.73765 | K5: 121.99486
B6: GDP | C6: HRV | D6: 56.2129 | E6: 58.233848 | F6: 74.856948 | G6: 85.023211 | H6: 92.060786 | I6: 96.605247 | J6: 99.595655 | K6: 101.65002
B7: GDP | C7: CYP | D7: 22.870805 | E7: 23.497388 | F7: 30.976343 | G7: 35.706114 | H7: 40.475247 | I7: 45.131654 | J7: 49.771373 | K7: 54.453476
B8: GDP | C8: CZE | D8: 218.62702 | E8: 234.16188 | F8: 251.41996 | G8: 273.21211 | H8: 293.98691 | I8: 314.62267 | J8: 334.82846 | K8: 354.71461
B9: GDP | C9: DNK | D9: 332.11886 | E9: 348.32493 | F9: 395.02206 | G9: 422.25814 | H9: 449.1125 | I9: 476.82871 | J9: 507.04088 | K9: 538.94297
B10: GDP | C10: EST | D10: 26.923978 | E10: 29.562598 | F10: 31.57923 | G10: 37.30497 | H10: 41.024369 | I10: 43.757605 | J10: 45.631199 | K10: 47.082899
B11: GDP | C11: FIN | D11: 256.96811 | E11: 268.79947 | F11: 286.37294 | G11: 307.90414 | H11: 326.0504 | I11: 344.72683 | J11: 363.85637 | K11: 383.69743
B12: GDP | C12: FRA | D12: 2640.2479 | E12: 2749.9288 | F12: 2944.7745 | G12: 3186.1687 | H12: 3398.4839 | I12: 3614.6787 | J12: 3835.2669 | K12: 4064.6585
B13: GDP | C13: DEU | D13: 3690.8157 | E13: 3870.7816 | F13: 4015.4807 | G13: 4227.0955 | H13: 4450.5663 | I13: 4713.0377 | J13: 4992.2584 | K13: 5262.1277
B14: GDP | C14: GRC | D14: 199.8516 | E14: 198.93647 | F14: 237.70095 | G14: 263.45347 | H14: 283.87666 | I14: 306.84436 | J14: 329.77694 | K14: 352.21309
... B142: POP | C142: ROW | D142: 7066.0704 | E142: 7315.8962 | F142: 7659.6725 | G142: 8005.0339 | H142: 8325.6818 | I142: 8619.4883 | J142: 8880.1327 | K142: 9102.8315

Sheet SECTOR_CHM_REC_INV
E2: 2017 | F2: 2020 | G2: 2025 | H2: 2030 | I2: 2035 | J2: 2040 | K2: 2045 | L2: 2050
B3: PROD | C3: AGR01 | D3: AUT | E3: 11.943814 | F3: 12.655291 | G3: 13.913544 | H3: 15.039789 | I3: 16.112217 | J3: 17.215948 | K3: 18.307696 | L3: 19.395617
B4: PROD | C4: AGR01 | D4: BEL | E4: 11.867644 | F4: 13.384678 | G4: 15.130764 | H4: 17.050137 | I4: 18.704691 | J4: 20.294372 | K4: 21.854745 | L4: 23.427139
B5: PROD | C5: AGR01 | D5: BGR | E5: 5.6849417 | F5: 5.9629062 | G5: 6.7642825 | H5: 7.4888225 | I5: 8.2914481 | J5: 9.0942379 | K5: 9.8516129 | L5: 10.54296
B6: PROD | C6: AGR01 | D6: HRV | E6: 3.524676 | F6: 3.466756 | G6: 4.1664908 | H6: 4.5197869 | I6: 4.7830565 | J6: 4.9573979 | K6: 5.0672768 | L6: 5.1352276
B7: PROD | C7: AGR01 | D7: CYP | E7: 0.95627791 | F7: 0.95130489 | G7: 1.1591208 | H7: 1.2850654 | I7: 1.4180463 | J7: 1.5564684 | K7: 1.6994989 | L7: 1.8472919
B8: PROD | C8: AGR01 | D8: CZE | E8: 8.7010166 | F8: 9.2380483 | G8: 10.642135 | H8: 11.791268 | I8: 12.899651 | J8: 13.971784 | K8: 15.035424 | L8: 16.105053
B9: PROD | C9: AGR01 | D9: DNK | E9: 12.63339 | F9: 13.004103 | G9: 15.210701 | H9: 16.601292 | I9: 17.906706 | J9: 19.239464 | K9: 20.657421 | L9: 22.184656
B10: PROD | C10: AGR01 | D10: EST | E10: 1.6875297 | F10: 1.9249808 | G10: 2.2440317 | H10: 2.6107379 | I10: 2.9407334 | J10: 3.2294746 | K10: 3.4740267 | L10: 3.6846337
B11: PROD | C11: AGR01 | D11: FIN | E11: 10.941716 | F11: 11.543592 | G11: 12.646272 | H11: 13.628045 | I11: 14.582959 | J11: 15.504782 | K11: 16.421538 | L11: 17.362053
B12: PROD | C12: AGR01 | D12: FRA | E12: 76.553209 | F12: 79.219189 | G12: 87.005344 | H12: 93.599478 | I12: 100.16077 | J12: 106.78549 | K12: 113.5324 | L12: 120.47583
B13: PROD | C13: AGR01 | D13: DEU | E13: 64.794826 | F13: 67.351723 | G13: 72.000369 | H13: 76.089185 | I13: 79.742627 | J13: 83.438455 | K13: 87.259034 | L13: 91.131171
B14: PROD | C14: AGR01 | D14: GRC | E14: 22.220988 | F14: 20.825087 | G14: 22.795879 | H14: 23.855226 | I14: 24.787146 | J14: 25.820687 | K14: 26.882927 | L14: 27.949796
... B199: PROD | C199: IND02 | D199: AUT | E199: 0.26673722 | F199: 0.2915694 | G199: 0.29846543 | H199: 0.31294849 | I199: 0.326099 | J199: 0.34791201 | K199: 0.36910558 | L199: 0.38901088
B200: PROD | C200: IND02 | D200: BEL | E200: 6.8625745e-15
B201: PROD | C201: IND02 | D201: BGR | E201: 0.0001203172 | F201: 0.00012960543 | G201: 0.00015320916 | H201: 0.00017559371 | I201: 0.00019699522 | J201: 0.00021667328 | K201: 0.00023484401 | L201: 0.00025235271
B202: PROD | C202: IND02 | D202: HRV | E202: 4.3792288e-15
B203: PROD | C203: IND02 | D203: CYP | E203: 0.00062859867 | F203: 0.00063707856 | G203: 0.00071372203 | H203: 0.00074751179 | I203: 0.00078843048 | J203: 0.00083555529 | K203: 0.00088353092 | L203: 0.00093203896
B204: PROD | C204: IND02 | D204: CZE | E204: 3.1416623e-15
B205: PROD | C205: IND02 | D205: DNK | E205: 1.1464409e-14 | F205: 1.2008501e-14 | G205: 1.3136115e-14 | H205: 1.3114886e-14 | I205: 1.3120821e-14 | J205: 1.3193716e-14 | K205: 1.3394099e-14 | L205: 1.3511488e-14
B206: PROD | C206: IND02 | D206: EST | E206: 0.0011027514 | F206: 0.0011099329 | G206: 0.0010842909 | H206: 0.00094494382 | I206: 0.00085894981 | J206: 0.00079849794 | K206: 0.00075035936 | L206: 0.00070576733
B207: PROD | C207: IND02 | D207: FIN | E207: 4.1400382e-15
B208: PROD | C208: IND02 | D208: FRA | E208: 3.5522718e-15
B209: PROD | C209: IND02 | D209: DEU | E209: 6.0971607e-15
B210: PROD | C210: IND02 | D210: GRC | E210: 0.12277949 | F210: 0.12615719 | G210: 0.16522511 | H210: 0.18998494 | I210: 0.21124729 | J210: 0.23550463 | K210: 0.25966649 | L210: 0.28325708
B211: PROD | C211: IND02 | D211: HUN | E211: 2.7997785e-15
B212: PROD | C212: IND02 | D212: IRL | E212: 0.00032003812 | F212: 0.0003426925 | G212: 0.00038891831 | H212: 0.0003907397 | I212: 0.00040276706 | J212: 0.00042324519 | K212: 0.00045105368 | L212: 0.00047957947
B213: PROD | C213: IND02 | D213: ITA | E213: 5.6936341e-15
B214: PROD | C214: IND02 | D214: LVA | E214: 0.0011365303 | F214: 0.0013274124 | G214: 0.0014185582 | H214: 0.0015349525 | I214: 0.0016312561 | J214: 0.0017048804 | K214: 0.0017458626 | L214: 0.0017717619
B215: PROD | C215: IND02 | D215: LTU | E215: 0.0017745435 | F215: 0.0020788956 | G215: 0.0023305141 | H215: 0.0025913055 | I215: 0.00282287 | J215: 0.0029951004 | K215: 0.0030940048 | L215: 0.0031171561
B216: PROD | C216: IND02 | D216: LUX | E216: 0.00057439647 | F216: 0.00071775907 | G216: 0.00071085771 | H216: 0.00079409364 | I216: 0.00085071021 | J216: 0.00089140646 | K216: 0.00091565226 | L216: 0.00093114681
B217: PROD | C217: IND02 | D217: MLT | E217: 0.00058422113 | F217: 0.00070217922 | G217: 0.00089945005 | H217: 0.0010674158 | I217: 0.0012372501 | J217: 0.001398623 | K217: 0.00154069 | L217: 0.0016641561
B218: PROD | C218: IND02 | D218: NLD | E218: 9.1154626e-15 | F218: 9.6009688e-15 | G218: 9.8863418e-15 | H218: 1.9947852e-14 | I218: 2.1005085e-14 | J218: 2.2256925e-14 | K218: 2.3256524e-14 | L218: 2.4122901e-14
B219: PROD | C219: IND02 | D219: POL | E219: 3.7645875e-15
B220: PROD | C220: IND02 | D220: PRT | E220: 3.9596e-15
B221: PROD | C221: IND02 | D221: ROU | E221: 1.7588236e-14 | F221: 2.0921665e-14 | G221: 2.5202412e-14 | H221: 2.7891107e-14 | I221: 3.0097166e-14 | J221: 3.1629773e-14 | K221: 3.2454881e-14 | L221: 3.276623e-14
B222: PROD | C222: IND02 | D222: SVK | E222: 9.4635051e-14 | F222: 1.0476441e-13 | G222: 1.1469642e-13 | H222: 1.2549556e-13 | I222: 1.3631188e-13 | J222: 1.4693451e-13 | K222: 1.5589478e-13 | L222: 1.6393122e-13
B223: PROD | C223: IND02 | D223: SVN | E223: 5.4730781e-14 | F223: 7.1175259e-14 | G223: 8.3007167e-14 | H223: 9.1524017e-14 | I223: 9.8229229e-14 | J223: 8.4802088e-14 | K223: 8.8241462e-14 | L223: 9.170752e-14
B224: PROD | C224: IND02 | D224: ESP | E224: 1.7419146e-15
B225: PROD | C225: IND02 | D225: SWE | E225: 2.9639869 | F225: 3.2625579 | G225: 3.4969738 | H225: 3.8054836 | I225: 4.136905 | J225: 4.4862504 | K225: 4.8401276 | L225: 5.1941469
...

Sheet MACRO_CHM_REC_OIL
D2: 2017 | E2: 2020 | F2: 2025 | G2: 2030 | H2: 2035 | I2: 2040 | J2: 2045 | K2: 2050
B3: GDP | C3: AUT | D3: 417.26098 | E3: 442.97251 | F3: 467.51373 | G3: 508.84388 | H3: 541.34503 | I3: 574.08979 | J3: 607.3528 | K3: 639.51211
B4: GDP | C4: BEL | D4: 502.76157 | E4: 556.64599 | F4: 580.98964 | G4: 616.41975 | H4: 654.21108 | I4: 689.73836 | J4: 724.00473 | K4: 758.90199
B5: GDP | C5: BGR | D5: 59.198664 | E5: 63.359287 | F5: 74.739607 | G5: 84.18632 | H5: 93.672146 | I5: 102.07077 | J5: 109.86153 | K5: 117.55301
B6: GDP | C6: HRV | D6: 56.2129 | E6: 58.233848 | F6: 74.856953 | G6: 83.322807 | H6: 89.792754 | I6: 93.908368 | J6: 96.578377 | K6: 98.388402
B7: GDP | C7: CYP | D7: 22.870805 | E7: 23.497388 | F7: 30.976297 | G7: 34.974352 | H7: 39.468712 | I7: 43.853981 | J7: 48.229067 | K7: 52.652268
B8: GDP | C8: CZE | D8: 218.62702 | E8: 234.16188 | F8: 251.42007 | G8: 269.5856 | H8: 288.95528 | I8: 308.31723 | J8: 327.36413 | K8: 346.18541
B9: GDP | C9: DNK | D9: 332.11886 | E9: 348.32493 | F9: 395.02289 | G9: 418.63546 | H9: 444.01147 | I9: 470.40128 | J9: 499.35355 | K9: 530.0394
B10: GDP | C10: EST | D10: 26.923978 | E10: 29.562598 | F10: 31.579197 | G10: 36.631997 | H10: 40.111242 | I10: 42.653299 | J10: 44.381835 | K10: 45.720628
B11: GDP | C11: FIN | D11: 256.96811 | E11: 268.79947 | F11: 286.37282 | G11: 302.85503 | H11: 319.69181 | I11: 337.14381 | J11: 355.1129 | K11: 373.8334
B12: GDP | C12: FRA | D12: 2640.2479 | E12: 2749.9288 | F12: 2944.768 | G12: 3153.608 | H12: 3353.2113 | I12: 3557.7537 | J12: 3767.4801 | K12: 3986.4835
B13: GDP | C13: DEU | D13: 3690.8157 | E13: 3870.7816 | F13: 4015.3022 | G13: 4180.7536 | H13: 4388.9152 | I13: 4636.91 | J13: 4902.3531 | K13: 5159.4743
B14: GDP | C14: GRC | D14: 199.8516 | E14: 198.93647 | F14: 237.70066 | G14: 252.81624 | H14: 270.65344 | I14: 290.79682 | J14: 310.94172 | K14: 330.68354
... B142: POP | C142: ROW | D142: 7066.0704 | E142: 7315.8962 | F142: 7659.6725 | G142: 8005.0339 | H142: 8325.6818 | I142: 8619.4883 | J142: 8880.1327 | K142: 9102.8315

Sheet SECTOR_CHM_REC_OIL
E2: 2017 | F2: 2020 | G2: 2025 | H2: 2030 | I2: 2035 | J2: 2040 | K2: 2045 | L2: 2050
B3: PROD | C3: AGR01 | D3: AUT | E3: 11.943814 | F3: 12.655291 | G3: 13.914252 | H3: 14.621986 | I3: 15.568032 | J3: 16.554476 | K3: 17.538481 | L3: 18.52335
B4: PROD | C4: AGR01 | D4: BEL | E4: 11.867644 | F4: 13.384678 | G4: 15.131091 | H4: 16.190926 | I4: 17.607797 | J4: 18.981287 | K4: 20.339617 | L4: 21.718517
B5: PROD | C5: AGR01 | D5: BGR | E5: 5.6849417 | F5: 5.9629062 | G5: 6.7647351 | H5: 7.1682493 | I5: 7.8838433 | J5: 8.6061571 | K5: 9.2946034 | L5: 9.9304606
B6: PROD | C6: AGR01 | D6: HRV | E6: 3.524676 | F6: 3.466756 | G6: 4.1666172 | H6: 4.3314557 | I6: 4.5633625 | J6: 4.7143611 | K6: 4.8079487 | L6: 4.8646455
B7: PROD | C7: AGR01 | D7: CYP | E7: 0.95627791 | F7: 0.95130489 | G7: 1.1591414 | H7: 1.2113774 | I7: 1.3301952 | J7: 1.4542864 | K7: 1.5829576 | L7: 1.716294
B8: PROD | C8: AGR01 | D8: CZE | E8: 8.7010166 | F8: 9.2380483 | G8: 10.64278 | H8: 11.436148 | I8: 12.429077 | J8: 13.396176 | K8: 14.361121 | L8: 15.334946
B9: PROD | C9: AGR01 | D9: DNK | E9: 12.63339 | F9: 13.004103 | G9: 15.210733 | H9: 15.793743 | I9: 16.938379 | J9: 18.121291 | K9: 19.392581 | L9: 20.768413
B10: PROD | C10: AGR01 | D10: EST | E10: 1.6875297 | F10: 1.9249808 | G10: 2.2440892 | H10: 2.3830474 | I10: 2.6613131 | J10: 2.902321 | K10: 3.1034762 | L10: 3.2753948
B11: PROD | C11: AGR01 | D11: FIN | E11: 10.941716 | F11: 11.543592 | G11: 12.646665 | H11: 13.042762 | I11: 13.874309 | J11: 14.686882 | K11: 15.502824 | L11: 16.346556
B12: PROD | C12: AGR01 | D12: FRA | E12: 76.553209 | F12: 79.219189 | G12: 87.00756 | H12: 90.365631 | I12: 96.137047 | J12: 102.0353 | K12: 108.09368 | L12: 114.37143
B13: PROD | C13: AGR01 | D13: DEU | E13: 64.794826 | F13: 67.351723 | G13: 72.033566 | H13: 76.52408 | I13: 79.841756 | J13: 83.27244 | K13: 86.871872 | L13: 90.545408
B14: PROD | C14: AGR01 | D14: GRC | E14: 22.220988 | F14: 20.825087 | G14: 22.796151 | H14: 23.847965 | I14: 24.690397 | J14: 25.652635 | K14: 26.652256 | L14: 27.662752
... B199: PROD | C199: IND02 | D199: AUT | E199: 0.26673722 | F199: 0.2915694 | G199: 0.2984821 | H199: 0.33485276 | I199: 0.34841574 | J199: 0.37136723 | K199: 0.39375699 | L199: 0.41499064
B200: PROD | C200: IND02 | D200: BEL | E200: 6.8625745e-15
B201: PROD | C201: IND02 | D201: BGR | E201: 0.0001203172 | F201: 0.00012960543 | G201: 0.00015320685 | H201: 0.00017111005 | I201: 0.00019065784 | J201: 0.00020860722 | K201: 0.00022517409 | L201: 0.00024118021
B202: PROD | C202: IND02 | D202: HRV | E202: 4.3792288e-15
B203: PROD | C203: IND02 | D203: CYP | E203: 0.00062859867 | F203: 0.00063707856 | G203: 0.00071366939 | H203: 0.00071845828 | I203: 0.00075378022 | J203: 0.00079529561 | K203: 0.00083814967 | L203: 0.00088206531
B204: PROD | C204: IND02 | D204: CZE | E204: 3.1416623e-15
B205: PROD | C205: IND02 | D205: DNK | E205: 1.1464409e-14 | F205: 1.2008501e-14 | G205: 1.3135175e-14 | H205: 1.4821321e-14 | I205: 1.4881664e-14 | J205: 1.5064426e-14 | K205: 1.5250328e-14 | L205: 1.548219e-14
B206: PROD | C206: IND02 | D206: EST | E206: 0.0011027514 | F206: 0.0011099329 | G206: 0.0010842532 | H206: 0.0010916571 | I206: 0.00099704796 | J206: 0.00092935173 | K206: 0.00087525409 | L206: 0.00082512157
B207: PROD | C207: IND02 | D207: FIN | E207: 4.1400382e-15
B208: PROD | C208: IND02 | D208: FRA | E208: 3.5522718e-15
B209: PROD | C209: IND02 | D209: DEU | E209: 6.0971607e-15
B210: PROD | C210: IND02 | D210: GRC | E210: 0.12277949 | F210: 0.12615719 | G210: 0.16522109 | H210: 0.11695646 | I210: 0.12718599 | J210: 0.1387927 | K210: 0.15038992 | L210: 0.16177505
B211: PROD | C211: IND02 | D211: HUN | E211: 2.7997785e-15
B212: PROD | C212: IND02 | D212: IRL | E212: 0.00032003812 | F212: 0.0003426925 | G212: 0.00038892153 | H212: 0.00043309677 | I212: 0.00044782047 | J212: 0.00047161126 | K212: 0.00050365292 | L212: 0.00053667158
B213: PROD | C213: IND02 | D213: ITA | E213: 5.6936341e-15 | L213: 8.2673179e-15
B214: PROD | C214: IND02 | D214: LVA | E214: 0.0011365303 | F214: 0.0013274124 | G214: 0.0014184472 | H214: 0.0015983008 | I214: 0.0016923993 | J214: 0.0017632055 | K214: 0.001801901 | L214: 0.0018271361
B215: PROD | C215: IND02 | D215: LTU | E215: 0.0017745435 | F215: 0.0020788956 | G215: 0.0023303734 | H215: 0.0029040634 | I215: 0.0031583138 | J215: 0.0033446477 | K215: 0.0034502795 | L215: 0.0034735858
B216: PROD | C216: IND02 | D216: LUX | E216: 0.00057439647 | F216: 0.00071775907 | G216: 0.00071090967 | H216: 0.0007624188 | I216: 0.00081197395 | J216: 0.000847253 | K216: 0.00086755528 | L216: 0.00088019745
B217: PROD | C217: IND02 | D217: MLT | E217: 0.00058422113 | F217: 0.00070217922 | G217: 0.00089944952 | H217: 0.0012368693 | I217: 0.0014371966 | J217: 0.0016296124 | K217: 0.001801035 | L217: 0.0019516125
B218: PROD | C218: IND02 | D218: NLD | E218: 9.1154626e-15 | F218: 9.6009688e-15 | G218: 9.8541597e-15 | H218: 2.1130811e-14 | I218: 2.2470082e-14 | J218: 2.3617185e-14 | K218: 2.4682459e-14 | L218: 2.5657372e-14
B219: PROD | C219: IND02 | D219: POL | E219: 3.7645875e-15
B220: PROD | C220: IND02 | D220: PRT | E220: 3.9596e-15
B221: PROD | C221: IND02 | D221: ROU | E221: 1.7588236e-14 | F221: 2.0921665e-14 | G221: 2.5192979e-14 | H221: 2.8653482e-14 | I221: 3.0838106e-14 | J221: 3.2365512e-14 | K221: 3.32136e-14 | L221: 3.3561634e-14
B222: PROD | C222: IND02 | D222: SVK | E222: 9.4635051e-14 | F222: 1.0476441e-13 | G222: 1.1467353e-13 | H222: 1.0577339e-13 | I222: 1.1448428e-13 | J222: 1.2301202e-13 | K222: 1.3035828e-13 | L222: 1.3700797e-13
B223: PROD | C223: IND02 | D223: SVN | E223: 5.4730781e-14 | F223: 7.1175259e-14 | H223: 6.7543908e-14 | I223: 7.211709e-14 | J223: 7.5926114e-14 | K223: 7.8789479e-14 | L223: 8.1698244e-14
B224: PROD | C224: IND02 | D224: ESP | E224: 1.7419146e-15
B225: PROD | C225: IND02 | D225: SWE | E225: 2.9639869 | F225: 3.2625579 | G225: 3.4971057 | H225: 3.753165 | I225: 4.0671108 | J225: 4.398631 | K225: 4.7355277 | L225: 5.0737465
...

Sheet MACRO_CHM_REC_INV_OIL
D2: 2017 | E2: 2020 | F2: 2025 | G2: 2030 | H2: 2035 | I2: 2040 | J2: 2045 | K2: 2050
B3: GDP | C3: AUT | D3: 417.26098 | E3: 442.97251 | F3: 467.51347 | G3: 508.83999 | H3: 541.34326 | I3: 574.08992 | J3: 607.35462 | K3: 639.51541
B4: GDP | C4: BEL | D4: 502.76157 | E4: 556.64599 | F4: 580.99139 | G4: 616.41421 | H4: 654.2083 | I4: 689.73789 | J4: 724.00622 | K4: 758.90515
B5: GDP | C5: BGR | D5: 59.198664 | E5: 63.359287 | F5: 74.739757 | G5: 84.185483 | H5: 93.671652 | I5: 102.07059 | J5: 109.86163 | K5: 117.55337
B6: GDP | C6: HRV | D6: 56.2129 | E6: 58.233848 | F6: 74.856948 | G6: 83.322209 | H6: 89.79241 | I6: 93.908247 | J6: 96.57844 | K6: 98.388614
B7: GDP | C7: CYP | D7: 22.870805 | E7: 23.497388 | F7: 30.976343 | G7: 34.974199 | H7: 39.468631 | I7: 43.853974 | J7: 48.229132 | K7: 52.652399
B8: GDP | C8: CZE | D8: 218.62702 | E8: 234.16188 | F8: 251.41996 | G8: 269.58275 | H8: 288.95374 | I8: 308.31685 | J8: 327.36477 | K8: 346.18696
B9: GDP | C9: DNK | D9: 332.11886 | E9: 348.32493 | F9: 395.02206 | G9: 418.6338 | H9: 444.01084 | I9: 470.40154 | J9: 499.35459 | K9: 530.04113
B10: GDP | C10: EST | D10: 26.923978 | E10: 29.562598 | F10: 31.57923 | G10: 36.63173 | H10: 40.111109 | I10: 42.65328 | J10: 44.381909 | K10: 45.720777
B11: GDP | C11: FIN | D11: 256.96811 | E11: 268.79947 | F11: 286.37294 | G11: 302.85338 | H11: 319.69091 | I11: 337.14358 | J11: 355.11326 | K11: 373.83429
B12: GDP | C12: FRA | D12: 2640.2479 | E12: 2749.9288 | F12: 2944.7745 | G12: 3153.5907 | H12: 3353.201 | I12: 3557.7499 | J12: 3767.4822 | K12: 3986.4911
B13: GDP | C13: DEU | D13: 3690.8157 | E13: 3870.7816 | F13: 4015.4807 | G13: 4182.3919 | H13: 4390.6367 | I13: 4638.7142 | J13: 4904.2306 | K13: 5161.408
B14: GDP | C14: GRC | D14: 199.8516 | E14: 198.93647 | F14: 237.70095 | G14: 252.81493 | H14: 270.65261 | I14: 290.79644 | J14: 310.94178 | K14: 330.68401
... B142: POP | C142: ROW | D142: 7066.0704 | E142: 7315.8962 | F142: 7659.6725 | G142: 8005.0339 | H142: 8325.6818 | I142: 8619.4883 | J142: 8880.1327 | K142: 9102.8315

Sheet SECTOR_CHM_REC_INV_OIL
E2: 2017 | F2: 2020 | G2: 2025 | H2: 2030 | I2: 2035 | J2: 2040 | K2: 2045 | L2: 2050
B3: PROD | C3: AGR01 | D3: AUT | E3: 11.943814 | F3: 12.655291 | G3: 13.913544 | H3: 14.621543 | I3: 15.567696 | J3: 16.554236 | K3: 17.538328 | L3: 18.523274
B4: PROD | C4: AGR01 | D4: BEL | E4: 11.867644 | F4: 13.384678 | G4: 15.130764 | H4: 16.190986 | I4: 17.608002 | J4: 18.981623 | K4: 20.340066 | L4: 21.719064
B5: PROD | C5: AGR01 | D5: BGR | E5: 5.6849417 | F5: 5.9629062 | G5: 6.7642825 | H5: 7.1681785 | I5: 7.8838227 | J5: 8.6061822 | K5: 9.2946675 | L5: 9.9305563
B6: PROD | C6: AGR01 | D6: HRV | E6: 3.524676 | F6: 3.466756 | G6: 4.1664908 | H6: 4.3314241 | I6: 4.5633483 | J6: 4.7143609 | K6: 4.8079592 | L6: 4.8646639
B7: PROD | C7: AGR01 | D7: CYP | E7: 0.95627791 | F7: 0.95130489 | G7: 1.1591208 | H7: 1.2113825 | I7: 1.3302048 | J7: 1.4543002 | K7: 1.5829753 | L7: 1.7163151
B8: PROD | C8: AGR01 | D8: CZE | E8: 8.7010166 | F8: 9.2380483 | G8: 10.642135 | H8: 11.435705 | I8: 12.428727 | J8: 13.395915 | K8: 14.360942 | L8: 15.334843
B9: PROD | C9: AGR01 | D9: DNK | E9: 12.63339 | F9: 13.004103 | G9: 15.210701 | H9: 15.79404 | I9: 16.938763 | J9: 18.121753 | K9: 19.393114 | L9: 20.769009
B10: PROD | C10: AGR01 | D10: EST | E10: 1.6875297 | F10: 1.9249808 | G10: 2.2440317 | H10: 2.38304 | I10: 2.6613241 | J10: 2.9023478 | K10: 3.1035157 | L10: 3.2754443
B11: PROD | C11: AGR01 | D11: FIN | E11: 10.941716 | F11: 11.543592 | G11: 12.646272 | H11: 13.042696 | I11: 13.874315 | J11: 14.686952 | K11: 15.502952 | L11: 16.346735
B12: PROD | C12: AGR01 | D12: FRA | E12: 76.553209 | F12: 79.219189 | G12: 87.005344 | H12: 90.365485 | I12: 96.137311 | J12: 102.03595 | K12: 108.09467 | L12: 114.37274
B13: PROD | C13: AGR01 | D13: DEU | E13: 64.794826 | F13: 67.351723 | G13: 72.000369 | H13: 76.561356 | I13: 79.880386 | J13: 83.312133 | K13: 86.912312 | L13: 90.586246
B14: PROD | C14: AGR01 | D14: GRC | E14: 22.220988 | F14: 20.825087 | G14: 22.795879 | H14: 23.847957 | I14: 24.690461 | J14: 25.652763 | K14: 26.652441 | L14: 27.662987
... B199: PROD | C199: IND02 | D199: AUT | E199: 0.26673722 | F199: 0.2915694 | G199: 0.29846543 | H199: 0.33486011 | I199: 0.34842626 | J199: 0.37138048 | K199: 0.3937725 | L199: 0.41500806
B200: PROD | C200: IND02 | D200: BEL | E200: 6.8625745e-15
B201: PROD | C201: IND02 | D201: BGR | E201: 0.0001203172 | F201: 0.00012960543 | G201: 0.00015320916 | H201: 0.00017110646 | I201: 0.00019065473 | J201: 0.00020860519 | K201: 0.00022517276 | L201: 0.00024117953
B202: PROD | C202: IND02 | D202: HRV | E202: 4.3792288e-15
B203: PROD | C203: IND02 | D203: CYP | E203: 0.00062859867 | F203: 0.00063707856 | G203: 0.00071372203 | H203: 0.00071844489 | I203: 0.00075376925 | J203: 0.0007952863 | K203: 0.00083814175 | L203: 0.00088205866
B204: PROD | C204: IND02 | D204: CZE | E204: 3.1416623e-15
B205: PROD | C205: IND02 | D205: DNK | E205: 1.1464409e-14 | F205: 1.2008501e-14 | G205: 1.3136115e-14 | H205: 1.4821609e-14 | I205: 1.4881967e-14 | J205: 1.499637e-14 | K205: 1.5181391e-14 | L205: 1.5472955e-14
B206: PROD | C206: IND02 | D206: EST | E206: 0.0011027514 | F206: 0.0011099329 | G206: 0.0010842909 | H206: 0.0010916429 | I206: 0.00099703997 | J206: 0.00092934713 | K206: 0.00087525159 | L206: 0.00082512047
B207: PROD | C207: IND02 | D207: FIN | E207: 4.1400382e-15
B208: PROD | C208: IND02 | D208: FRA | E208: 3.5522718e-15
B209: PROD | C209: IND02 | D209: DEU | E209: 6.0971607e-15
B210: PROD | C210: IND02 | D210: GRC | E210: 0.12277949 | F210: 0.12615719 | G210: 0.16522511 | H210: 0.11695496 | I210: 0.12718462 | J210: 0.13879142 | K210: 0.15038876 | L210: 0.16177402
B211: PROD | C211: IND02 | D211: HUN | E211: 2.7997785e-15
B212: PROD | C212: IND02 | D212: IRL | E212: 0.00032003812 | F212: 0.0003426925 | G212: 0.00038891831 | H212: 0.00043309959 | I212: 0.00044782475 | J212: 0.00047161718 | K212: 0.0005036598 | L212: 0.00053667932
B213: PROD | C213: IND02 | D213: ITA | E213: 5.6936341e-15
B214: PROD | C214: IND02 | D214: LVA | E214: 0.0011365303 | F214: 0.0013274124 | G214: 0.0014185582 | H214: 0.0015982545 | I214: 0.0016923669 | J214: 0.0017631842 | K214: 0.0018018884 | L214: 0.0018271309
B215: PROD | C215: IND02 | D215: LTU | E215: 0.0017745435 | F215: 0.0020788956 | G215: 0.0023305141 | H215: 0.0029039691 | I215: 0.0031582463 | J215: 0.0033446012 | K215: 0.0034502502 | L215: 0.0034735714
B216: PROD | C216: IND02 | D216: LUX | E216: 0.00057439647 | F216: 0.00071775907 | G216: 0.00071085771 | H216: 0.00076245689 | I216: 0.00081202022 | J216: 0.00084730391 | K216: 0.00086760808 | L216: 0.00088025042
B217: PROD | C217: IND02 | D217: MLT | E217: 0.00058422113 | F217: 0.00070217922 | G217: 0.00089945005 | H217: 0.0012368692 | I217: 0.0014372033 | J217: 0.0016296235 | K217: 0.001801049 | L217: 0.0019516284
B218: PROD | C218: IND02 | D218: NLD | E218: 9.1154626e-15 | F218: 9.6009688e-15 | G218: 9.8863418e-15 | H218: 2.1160107e-14 | I218: 2.2300497e-14 | J218: 2.3424573e-14 | K218: 2.4663719e-14 | L218: 2.5658465e-14
B219: PROD | C219: IND02 | D219: POL | E219: 3.7645875e-15
B220: PROD | C220: IND02 | D220: PRT | E220: 3.9596e-15
B221: PROD | C221: IND02 | D221: ROU | E221: 1.7588236e-14 | F221: 2.0921665e-14 | G221: 2.5202412e-14 | H221: 2.8652215e-14 | I221: 3.0836888e-14 | J221: 3.2360933e-14 | K221: 3.321445e-14 | L221: 3.356124e-14
B222: PROD | C222: IND02 | D222: SVK | E222: 9.4635051e-14 | F222: 1.0476441e-13 | G222: 1.1469642e-13 | H222: 1.057856e-13 | I222: 1.1446319e-13 | J222: 1.2300704e-13 | K222: 1.3033506e-13 | L222: 1.3697658e-13
B223: PROD | C223: IND02 | D223: SVN | E223: 5.4730781e-14 | F223: 7.1175259e-14 | G223: 8.3007167e-14 | H223: 6.7545308e-14 | I223: 7.2119768e-14 | J223: 7.5927875e-14 | K223: 7.8791373e-14 | L223: 8.1700182e-14
B224: PROD | C224: IND02 | D224: ESP | E224: 1.7419146e-15
B225: PROD | C225: IND02 | D225: SWE | E225: 2.9639869 | F225: 3.2625579 | G225: 3.4969738 | H225: 3.7534396 | I225: 4.0674124 | J225: 4.3989562 | K225: 4.7358727 | L225: 5.0741069
...

Sheet MACRO_BASE_OIL
D2: 2017 | E2: 2020 | F2: 2025 | G2: 2030 | H2: 2035 | I2: 2040 | J2: 2045 | K2: 2050
B3: GDP | C3: AUT | D3: 417.26098 | E3: 442.97251 | F3: 467.51373 | G3: 508.85126 | H3: 541.35771 | I3: 574.10741 | J3: 607.37499 | K3: 639.53849
B4: GDP | C4: BEL | D4: 502.76157 | E4: 556.64599 | F4: 580.98964 | G4: 616.43073 | H4: 654.22073 | I4: 689.74738 | J4: 724.01381 | K4: 758.91184
B5: GDP | C5: BGR | D5: 59.198664 | E5: 63.359287 | F5: 74.739607 | G5: 84.186637 | H5: 93.673333 | I5: 102.07277 | J5: 109.86428 | K5: 117.55648
B6: GDP | C6: HRV | D6: 56.2129 | E6: 58.233848 | F6: 74.856953 | G6: 83.32313 | H6: 89.793779 | I6: 93.909965 | J6: 96.580429 | K6: 98.390819
B7: GDP | C7: CYP | D7: 22.870805 | E7: 23.497388 | F7: 30.976297 | G7: 34.974353 | H7: 39.468932 | I7: 43.854414 | J7: 48.229698 | K7: 52.653077
B8: GDP | C8: CZE | D8: 218.62702 | E8: 234.16188 | F8: 251.42007 | G8: 269.58932 | H8: 288.96284 | I8: 308.32817 | J8: 327.37815 | K8: 346.20228
B9: GDP | C9: DNK | D9: 332.11886 | E9: 348.32493 | F9: 395.02289 | G9: 418.63815 | H9: 444.01652 | I9: 470.40832 | J9: 499.36233 | K9: 530.04975
B10: GDP | C10: EST | D10: 26.923978 | E10: 29.562598 | F10: 31.579197 | G10: 36.632039 | H10: 40.111611 | I10: 42.653947 | J10: 44.382715 | K10: 45.721699
B11: GDP | C11: FIN | D11: 256.96811 | E11: 268.79947 | F11: 286.37282 | G11: 302.85599 | H11: 319.69437 | I11: 337.14786 | J11: 355.11838 | K11: 373.84024
B12: GDP | C12: FRA | D12: 2640.2479 | E12: 2749.9288 | F12: 2944.768 | G12: 3153.6287 | H12: 3353.2408 | I12: 3557.7929 | J12: 3767.5296 | K12: 3986.544
B13: GDP | C13: DEU | D13: 3690.8157 | E13: 3870.7816 | F13: 4015.3022 | G13: 4181.3923 | H13: 4389.746 | I13: 4637.9307 | J13: 4903.5455 | K13: 5160.8084
B14: GDP | C14: GRC | D14: 199.8516 | E14: 198.93647 | F14: 237.70066 | G14: 252.81668 | H14: 270.65526 | I14: 290.79992 | J14: 310.94602 | K14: 330.68894
... B142: POP | C142: ROW | D142: 7066.0704 | E142: 7315.8962 | F142: 7659.6725 | G142: 8005.0339 | H142: 8325.6818 | I142: 8619.4883 | J142: 8880.1327 | K142: 9102.8315

Sheet SECTOR_BASE_OIL
E2: 2017 | F2: 2020 | G2: 2025 | H2: 2030 | I2: 2035 | J2: 2040 | K2: 2045 | L2: 2050
B3: PROD | C3: AGR01 | D3: AUT | E3: 11.943814 | F3: 12.655291 | G3: 13.914252 | H3: 14.620271 | I3: 15.566649 | J3: 16.553418 | K3: 17.537738 | L3: 18.522891
B4: PROD | C4: AGR01 | D4: BEL | E4: 11.867644 | F4: 13.384678 | G4: 15.131091 | H4: 16.185978 | I4: 17.60305 | J4: 18.97685 | K4: 20.335528 | L4: 21.714759
B5: PROD | C5: AGR01 | D5: BGR | E5: 5.6849417 | F5: 5.9629062 | G5: 6.7647351 | H5: 7.1682241 | I5: 7.8839671 | J5: 8.6064414 | K5: 9.2950409 | L5: 9.9310302
B6: PROD | C6: AGR01 | D6: HRV | E6: 3.524676 | F6: 3.466756 | G6: 4.1666172 | H6: 4.3315068 | I6: 4.5634505 | J6: 4.7144772 | K6: 4.8080844 | L6: 4.864794
B7: PROD | C7: AGR01 | D7: CYP | E7: 0.95627791 | F7: 0.95130489 | G7: 1.1591414 | H7: 1.2113979 | I7: 1.330227 | J7: 1.454328 | K7: 1.5830078 | L7: 1.7163516
B8: PROD | C8: AGR01 | D8: CZE | E8: 8.7010166 | F8: 9.2380483 | G8: 10.64278 | H8: 11.434753 | I8: 12.427917 | J8: 13.395278 | K8: 14.360478 | L8: 15.334534
B9: PROD | C9: AGR01 | D9: DNK | E9: 12.63339 | F9: 13.004103 | G9: 15.210733 | H9: 15.79265 | I9: 16.937507 | J9: 18.120674 | K9: 19.392215 | L9: 20.768274
B10: PROD | C10: AGR01 | D10: EST | E10: 1.6875297 | F10: 1.9249808 | G10: 2.2440892 | H10: 2.3830512 | I10: 2.6613596 | J10: 2.9024073 | K10: 3.1035962 | L10: 3.2755422
B11: PROD | C11: AGR01 | D11: FIN | E11: 10.941716 | F11: 11.543592 | G11: 12.646665 | H11: 13.042608 | I11: 13.874327 | J11: 14.687076 | K11: 15.503187 | L11: 16.347074
B12: PROD | C12: AGR01 | D12: FRA | E12: 76.553209 | F12: 79.219189 | G12: 87.00756 | H12: 90.361102 | I12: 96.133342 | J12: 102.03255 | K12: 108.09189 | L12: 114.37055
B13: PROD | C13: AGR01 | D13: DEU | E13: 64.794826 | F13: 67.351723 | G13: 72.033566 | H13: 76.610733 | I13: 79.931178 | J13: 83.362242 | K13: 86.961021 | L13: 90.633802
B14: PROD | C14: AGR01 | D14: GRC | E14: 22.220988 | F14: 20.825087 | G14: 22.796151 | H14: 23.847908 | I14: 24.690542 | J14: 25.65297 | K14: 26.652765 | L14: 27.663416
... B199: PROD | C199: IND02 | D199: AUT | E199: 0.26673722 | F199: 0.2915694 | G199: 0.2984821 | H199: 0.33486739 | I199: 0.34844238 | J199: 0.37140417 | K199: 0.39380295 | L199: 0.41504468
B200: PROD | C200: IND02 | D200: BEL | E200: 6.8625745e-15
B201: PROD | C201: IND02 | D201: BGR | E201: 0.0001203172 | F201: 0.00012960543 | G201: 0.00015320685 | H201: 0.00017114421 | I201: 0.00019069451 | J201: 0.00020864507 | K201: 0.00022521242 | L201: 0.0002412189
B202: PROD | C202: IND02 | D202: HRV | E202: 4.3792288e-15
B203: PROD | C203: IND02 | D203: CYP | E203: 0.00062859867 | F203: 0.00063707856 | G203: 0.00071366939 | H203: 0.00071836872 | I203: 0.00075369983 | J203: 0.00079522087 | K203: 0.00083807973 | L203: 0.00088199979
B204: PROD | C204: IND02 | D204: CZE | E204: 3.1416623e-15
B205: PROD | C205: IND02 | D205: DNK | E205: 1.1464409e-14 | F205: 1.2008501e-14 | G205: 1.3135175e-14 | H205: 1.4820658e-14 | I205: 1.4880685e-14 | J205: 1.4986602e-14 | K205: 1.5180393e-14 | L205: 1.5410975e-14
B206: PROD | C206: IND02 | D206: EST | E206: 0.0011027514 | F206: 0.0011099329 | G206: 0.0010842532 | H206: 0.001091534 | I206: 0.0009969614 | J206: 0.00092929081 | K206: 0.0008752116 | L206: 0.00082509311
B207: PROD | C207: IND02 | D207: FIN | E207: 4.1400382e-15
B208: PROD | C208: IND02 | D208: FRA | E208: 3.5522718e-15
B209: PROD | C209: IND02 | D209: DEU | E209: 6.0971607e-15
B210: PROD | C210: IND02 | D210: GRC | E210: 0.12277949 | F210: 0.12615719 | G210: 0.16522109 | H210: 0.11695527 | I210: 0.12718539 | J210: 0.13879263 | K210: 0.15039042 | L210: 0.16177614
B211: PROD | C211: IND02 | D211: HUN | E211: 2.7997785e-15
B212: PROD | C212: IND02 | D212: IRL | E212: 0.00032003812 | F212: 0.0003426925 | G212: 0.00038892153 | H212: 0.00043304672 | I212: 0.00044777826 | J212: 0.00047157289 | K212: 0.00050361727 | L212: 0.00053663833
B213: PROD | C213: IND02 | D213: ITA | E213: 5.6936341e-15 | L213: 8.2673182e-15
B214: PROD | C214: IND02 | D214: LVA | E214: 0.0011365303 | F214: 0.0013274124 | G214: 0.0014184472 | H214: 0.0015979648 | I214: 0.001692119 | J214: 0.0017629794 | K214: 0.0018017284 | L214: 0.0018270106
B215: PROD | C215: IND02 | D215: LTU | E215: 0.0017745435 | F215: 0.0020788956 | G215: 0.0023303734 | H215: 0.0029033134 | I215: 0.0031576687 | J215: 0.0033441323 | K215: 0.0034498984 | L215: 0.0034733283
B216: PROD | C216: IND02 | D216: LUX | E216: 0.00057439647 | F216: 0.00071775907 | G216: 0.00071090967 | H216: 0.00076251369 | I216: 0.00081209029 | J216: 0.00084737939 | K216: 0.00086768291 | L216: 0.00088032203
B217: PROD | C217: IND02 | D217: MLT | E217: 0.00058422113 | F217: 0.00070217922 | G217: 0.00089944952 | H217: 0.0012368478 | I217: 0.0014371917 | J217: 0.0016296222 | K217: 0.0018010589 | L217: 0.0019516501
B218: PROD | C218: IND02 | D218: NLD | E218: 9.1154626e-15 | F218: 9.6009688e-15 | G218: 9.8541597e-15 | H218: 2.1318313e-14 | I218: 2.2288835e-14 | J218: 2.3381838e-14 | K218: 2.466336e-14 | L218: 2.5653665e-14
B219: PROD | C219: IND02 | D219: POL | E219: 3.7645875e-15
B220: PROD | C220: IND02 | D220: PRT | E220: 3.9596e-15
B221: PROD | C221: IND02 | D221: ROU | E221: 1.7588236e-14 | F221: 2.0921665e-14 | G221: 2.5192979e-14 | H221: 2.8653319e-14 | I221: 3.0838508e-14 | J221: 3.2367068e-14 | K221: 3.3222083e-14 | L221: 3.3576945e-14
B222: PROD | C222: IND02 | D222: SVK | E222: 9.4635051e-14 | F222: 1.0476441e-13 | G222: 1.1467353e-13 | H222: 1.0575045e-13 | I222: 1.1446446e-13 | J222: 1.2299619e-13 | K222: 1.303481e-13 | L222: 1.3698165e-13
B223: PROD | C223: IND02 | D223: SVN | E223: 5.4730781e-14 | F223: 7.1175259e-14 | H223: 6.7557758e-14 | I223: 7.2132438e-14 | J223: 7.5942988e-14 | K223: 7.8807388e-14 | L223: 8.1717309e-14
B224: PROD | C224: IND02 | D224: ESP | E224: 1.7419146e-15
B225: PROD | C225: IND02 | D225: SWE | E225: 2.9639869 | F225: 3.2625579 | G225: 3.4971057 | H225: 3.753701 | I225: 4.0677298 | J225: 4.399319 | K225: 4.7362745 | L225: 5.0745443
...

Sheet Macro_Figures
F1: Scenario
F2: 2017 | G2: 2020 | H2: 2025 | I2: 2030 | J2: 2035 | K2: 2040 | L2: 2045 | M2: 2050
B3: GDP | C3: DEU | D3: BASE | F3: =SUMIFS(MACRO_BASE!D$3:D$1000,MACRO_BASE!$B$3:$B$1000,$B3,MACRO_BASE!$C$3:$C$1000,$C3) -> 3690.8157 | G3: =SUMIFS(MACRO_BASE!E$3:E$1000,MACRO_BASE!$B$3:$B$1000,$B3,MACRO_BASE!$C$3:$C$1000,$C3) -> 3870.7816 | H3: =SUMIFS(MACRO_BASE!F$3:F$1000,MACRO_BASE!$B$3:$B$1000,$B3,MACRO_BASE!$C$3:$C$1000,$C3) -> 4015.3022 | I3: =SUMIFS(MACRO_BASE!G$3:G$1000,MACRO_BASE!$B$3:$B$1000,$B3,MACRO_BASE!$C$3:$C$1000,$C3) -> 4226.205 | J3: =SUMIFS(MACRO_BASE!H$3:H$1000,MACRO_BASE!$B$3:$B$1000,$B3,MACRO_BASE!$C$3:$C$1000,$C3) -> 4449.7564 | K3: =SUMIFS(MACRO_BASE!I$3:I$1000,MACRO_BASE!$B$3:$B$1000,$B3,MACRO_BASE!$C$3:$C$1000,$C3) -> 4712.3095 | L3: =SUMIFS(MACRO_BASE!J$3:J$1000,MACRO_BASE!$B$3:$B$1000,$B3,MACRO_BASE!$C$3:$C$1000,$C3) -> 4991.6061 | M3: =SUMIFS(MACRO_BASE!K$3:K$1000,MACRO_BASE!$B$3:$B$1000,$B3,MACRO_BASE!$C$3:$C$1000,$C3) -> 5261.5412
B4: GDP | C4: DEU | D4: BASE_OIL | F4: =SUMIFS(MACRO_BASE_OIL!D$3:D$1000,MACRO_BASE_OIL!$B$3:$B$1000,$B4,MACRO_BASE_OIL!$C$3:$C$1000,$C4) -> 3690.8157 | G4: =SUMIFS(MACRO_BASE_OIL!E$3:E$1000,MACRO_BASE_OIL!$B$3:$B$1000,$B4,MACRO_BASE_OIL!$C$3:$C$1000,$C4) -> 3870.7816 | H4: =SUMIFS(MACRO_BASE_OIL!F$3:F$1000,MACRO_BASE_OIL!$B$3:$B$1000,$B4,MACRO_BASE_OIL!$C$3:$C$1000,$C4) -> 4015.3022 | I4: =SUMIFS(MACRO_BASE_OIL!G$3:G$1000,MACRO_BASE_OIL!$B$3:$B$1000,$B4,MACRO_BASE_OIL!$C$3:$C$1000,$C4) -> 4181.3923 | J4: =SUMIFS(MACRO_BASE_OIL!H$3:H$1000,MACRO_BASE_OIL!$B$3:$B$1000,$B4,MACRO_BASE_OIL!$C$3:$C$1000,$C4) -> 4389.746 | K4: =SUMIFS(MACRO_BASE_OIL!I$3:I$1000,MACRO_BASE_OIL!$B$3:$B$1000,$B4,MACRO_BASE_OIL!$C$3:$C$1000,$C4) -> 4637.9307 | L4: =SUMIFS(MACRO_BASE_OIL!J$3:J$1000,MACRO_BASE_OIL!$B$3:$B$1000,$B4,MACRO_BASE_OIL!$C$3:$C$1000,$C4) -> 4903.5455 | M4: =SUMIFS(MACRO_BASE_OIL!K$3:K$1000,MACRO_BASE_OIL!$B$3:$B$1000,$B4,MACRO_BASE_OIL!$C$3:$C$1000,$C4) -> 5160.8084
B5: GDP | C5: DEU | D5: CHM_REC | F5: =SUMIFS(MACRO_CHM_REC!D$3:D$1000,MACRO_CHM_REC!$B$3:$B$1000,$B5,MACRO_CHM_REC!$C$3:$C$1000,$C5) -> 3690.8157 | G5: =SUMIFS(MACRO_CHM_REC!E$3:E$1000,MACRO_CHM_REC!$B$3:$B$1000,$B5,MACRO_CHM_REC!$C$3:$C$1000,$C5) -> 3870.7816 | H5: =SUMIFS(MACRO_CHM_REC!F$3:F$1000,MACRO_CHM_REC!$B$3:$B$1000,$B5,MACRO_CHM_REC!$C$3:$C$1000,$C5) -> 4015.3022 | I5: =SUMIFS(MACRO_CHM_REC!G$3:G$1000,MACRO_CHM_REC!$B$3:$B$1000,$B5,MACRO_CHM_REC!$C$3:$C$1000,$C5) -> 4225.4372 | J5: =SUMIFS(MACRO_CHM_REC!H$3:H$1000,MACRO_CHM_REC!$B$3:$B$1000,$B5,MACRO_CHM_REC!$C$3:$C$1000,$C5) -> 4448.8179 | K5: =SUMIFS(MACRO_CHM_REC!I$3:I$1000,MACRO_CHM_REC!$B$3:$B$1000,$B5,MACRO_CHM_REC!$C$3:$C$1000,$C5) -> 4711.2006 | L5: =SUMIFS(MACRO_CHM_REC!J$3:J$1000,MACRO_CHM_REC!$B$3:$B$1000,$B5,MACRO_CHM_REC!$C$3:$C$1000,$C5) -> 4990.3428 | M5: =SUMIFS(MACRO_CHM_REC!K$3:K$1000,MACRO_CHM_REC!$B$3:$B$1000,$B5,MACRO_CHM_REC!$C$3:$C$1000,$C5) -> 5260.1516
B6: GDP | C6: DEU | D6: CHM_REC_OIL | F6: =SUMIFS(MACRO_CHM_REC_OIL!D$3:D$1000,MACRO_CHM_REC_OIL!$B$3:$B$1000,$B6,MACRO_CHM_REC_OIL!$C$3:$C$1000,$C6) -> 3690.8157 | G6: =SUMIFS(MACRO_CHM_REC_OIL!E$3:E$1000,MACRO_CHM_REC_OIL!$B$3:$B$1000,$B6,MACRO_CHM_REC_OIL!$C$3:$C$1000,$C6) -> 3870.7816 | H6: =SUMIFS(MACRO_CHM_REC_OIL!F$3:F$1000,MACRO_CHM_REC_OIL!$B$3:$B$1000,$B6,MACRO_CHM_REC_OIL!$C$3:$C$1000,$C6) -> 4015.3022 | I6: =SUMIFS(MACRO_CHM_REC_OIL!G$3:G$1000,MACRO_CHM_REC_OIL!$B$3:$B$1000,$B6,MACRO_CHM_REC_OIL!$C$3:$C$1000,$C6) -> 4180.7536 | J6: =SUMIFS(MACRO_CHM_REC_OIL!H$3:H$1000,MACRO_CHM_REC_OIL!$B$3:$B$1000,$B6,MACRO_CHM_REC_OIL!$C$3:$C$1000,$C6) -> 4388.9152 | K6: =SUMIFS(MACRO_CHM_REC_OIL!I$3:I$1000,MACRO_CHM_REC_OIL!$B$3:$B$1000,$B6,MACRO_CHM_REC_OIL!$C$3:$C$1000,$C6) -> 4636.91 | L6: =SUMIFS(MACRO_CHM_REC_OIL!J$3:J$1000,MACRO_CHM_REC_OIL!$B$3:$B$1000,$B6,MACRO_CHM_REC_OIL!$C$3:$C$1000,$C6) -> 4902.3531 | M6: =SUMIFS(MACRO_CHM_REC_OIL!K$3:K$1000,MACRO_CHM_REC_OIL!$B$3:$B$1000,$B6,MACRO_CHM_REC_OIL!$C$3:$C$1000,$C6) -> 5159.4743
B7: GDP | C7: DEU | D7: CHM_REC_INV | F7: =SUMIFS(MACRO_CHM_REC_INV!D$3:D$1000,MACRO_CHM_REC_INV!$B$3:$B$1000,$B7,MACRO_CHM_REC_INV!$C$3:$C$1000,$C7) -> 3690.8157 | G7: =SUMIFS(MACRO_CHM_REC_INV!E$3:E$1000,MACRO_CHM_REC_INV!$B$3:$B$1000,$B7,MACRO_CHM_REC_INV!$C$3:$C$1000,$C7) -> 3870.7816 | H7: =SUMIFS(MACRO_CHM_REC_INV!F$3:F$1000,MACRO_CHM_REC_INV!$B$3:$B$1000,$B7,MACRO_CHM_REC_INV!$C$3:$C$1000,$C7) -> 4015.4807 | I7: =SUMIFS(MACRO_CHM_REC_INV!G$3:G$1000,MACRO_CHM_REC_INV!$B$3:$B$1000,$B7,MACRO_CHM_REC_INV!$C$3:$C$1000,$C7) -> 4227.0955 | J7: =SUMIFS(MACRO_CHM_REC_INV!H$3:H$1000,MACRO_CHM_REC_INV!$B$3:$B$1000,$B7,MACRO_CHM_REC_INV!$C$3:$C$1000,$C7) -> 4450.5663 | K7: =SUMIFS(MACRO_CHM_REC_INV!I$3:I$1000,MACRO_CHM_REC_INV!$B$3:$B$1000,$B7,MACRO_CHM_REC_INV!$C$3:$C$1000,$C7) -> 4713.0377 | L7: =SUMIFS(MACRO_CHM_REC_INV!J$3:J$1000,MACRO_CHM_REC_INV!$B$3:$B$1000,$B7,MACRO_CHM_REC_INV!$C$3:$C$1000,$C7) -> 4992.2584 | M7: =SUMIFS(MACRO_CHM_REC_INV!K$3:K$1000,MACRO_CHM_REC_INV!$B$3:$B$1000,$B7,MACRO_CHM_REC_INV!$C$3:$C$1000,$C7) -> 5262.1277
B8: GDP | C8: DEU | D8: CHM_REC_INV_OIL | F8: =SUMIFS(MACRO_CHM_REC_INV_OIL!D$3:D$1000,MACRO_CHM_REC_INV!$B$3:$B$1000,$B8,MACRO_CHM_REC_INV!$C$3:$C$1000,$C8) -> 3690.8157 | G8: =SUMIFS(MACRO_CHM_REC_INV_OIL!E$3:E$1000,MACRO_CHM_REC_INV!$B$3:$B$1000,$B8,MACRO_CHM_REC_INV!$C$3:$C$1000,$C8) -> 3870.7816 | H8: =SUMIFS(MACRO_CHM_REC_INV_OIL!F$3:F$1000,MACRO_CHM_REC_INV!$B$3:$B$1000,$B8,MACRO_CHM_REC_INV!$C$3:$C$1000,$C8) -> 4015.4807 | I8: =SUMIFS(MACRO_CHM_REC_INV_OIL!G$3:G$1000,MACRO_CHM_REC_INV!$B$3:$B$1000,$B8,MACRO_CHM_REC_INV!$C$3:$C$1000,$C8) -> 4182.3919 | J8: =SUMIFS(MACRO_CHM_REC_INV_OIL!H$3:H$1000,MACRO_CHM_REC_INV!$B$3:$B$1000,$B8,MACRO_CHM_REC_INV!$C$3:$C$1000,$C8) -> 4390.6367 | K8: =SUMIFS(MACRO_CHM_REC_INV_OIL!I$3:I$1000,MACRO_CHM_REC_INV!$B$3:$B$1000,$B8,MACRO_CHM_REC_INV!$C$3:$C$1000,$C8) -> 4638.7142 | L8: =SUMIFS(MACRO_CHM_REC_INV_OIL!J$3:J$1000,MACRO_CHM_REC_INV!$B$3:$B$1000,$B8,MACRO_CHM_REC_INV!$C$3:$C$1000,$C8) -> 4904.2306 | M8: =SUMIFS(MACRO_CHM_REC_INV_OIL!K$3:K$1000,MACRO_CHM_REC_INV!$B$3:$B$1000,$B8,MACRO_CHM_REC_INV!$C$3:$C$1000,$C8) -> 5161.408
F10: 2017 | G10: 2020 | H10: 2025 | I10: 2030 | J10: 2035 | K10: 2040 | L10: 2045 | M10: 2050
D11: CHM_REC_INV vs BASE | H11: 0 | I11: =I7/I3-1 -> 0.00021071331 | J11: =J7/J3-1 -> 0.00018202839 | K11: =K7/K3-1 -> 0.00015452114 | L11: =L7/L3-1 -> 0.00013068798 | M11: =M7/M3-1 -> 0.00011147234
D12: CHM_REC_INV_OIL vs BASE_OIL | H12: 0 | I12: =I8/I4-1 -> 0.00023907358 | J12: =J8/J4-1 -> 0.00020289726 | K12: =K8/K4-1 -> 0.0001689184 | L12: =L8/L4-1 -> 0.00013970434 | M12: =M8/M4-1 -> 0.00011618257
F15: 2017 | G15: 2020 | H15: 2025 | I15: 2030 | J15: 2035 | K15: 2040 | L15: 2045 | M15: 2050
D16: CHM_REC_INV vs BASE | H16: 0 | I16: =I7/I3-1 -> 0.00021071331 | J16: =J7/J3-1 -> 0.00018202839 | K16: =K7/K3-1 -> 0.00015452114 | L16: =L7/L3-1 -> 0.00013068798 | M16: =M7/M3-1 -> 0.00011147234
D17: CHM_REC vs BASE | H17: 0 | I17: =I5/I3-1 -> -0.00018166585 | J17: =J5/J3-1 -> -0.00021089599 | K17: =K5/K3-1 -> -0.00023532563 | L17: =L5/L3-1 -> -0.00025308193 | M17: =M5/M3-1 -> -0.0002641047
D18: CHM_REC_INV_OIL vs BASE_OIL | H18: 0 | I18: =I8/I4-1 -> 0.00023907358 | J18: =J8/J4-1 -> 0.00020289726 | K18: =K8/K4-1 -> 0.0001689184 | L18: =L8/L4-1 -> 0.00013970434 | M18: =M8/M4-1 -> 0.00011618257
D19: CHM_REC_OIL vs BASE_OIL | H19: 0 | I19: =I6/I4-1 -> -0.0001527443 | J19: =J6/J4-1 -> -0.00018926496 | K19: =K6/K4-1 -> -0.00022007199 | L19: =L6/L4-1 -> -0.00024317718 | M19: =M6/M4-1 -> -0.00025850474

Sheet Sectoral_Figures
G1: 2030 | H1: 2040 | I1: 2050
A2: PROD | B2: IND09 | C2: DEU | D2: Other chemicals | F2: BASE | G2: =SUMIFS(SECTOR_BASE!H$3:H$10000,SECTOR_BASE!$B$3:$B$10000,$A2,SECTOR_BASE!$C$3:$C$10000,$B2,SECTOR_BASE!$D$3:$D$10000,$C2) -> 209.52762 | H2: =SUMIFS(SECTOR_BASE!J$3:J$10000,SECTOR_BASE!$B$3:$B$10000,$A2,SECTOR_BASE!$C$3:$C$10000,$B2,SECTOR_BASE!$D$3:$D$10000,$C2) -> 230.43436 | I2: =SUMIFS(SECTOR_BASE!L$3:L$10000,SECTOR_BASE!$B$3:$B$10000,$A2,SECTOR_BASE!$C$3:$C$10000,$B2,SECTOR_BASE!$D$3:$D$10000,$C2) -> 254.33421
A3: PROD | B3: IND09 | C3: DEU | D3: Other chemicals | F3: BASE_OIL | G3: =SUMIFS(SECTOR_BASE_OIL!H$3:H$10000,SECTOR_BASE_OIL!$B$3:$B$10000,$A3,SECTOR_BASE_OIL!$C$3:$C$10000,$B3,SECTOR_BASE_OIL!$D$3:$D$10000,$C3) -> 207.22745 | H3: =SUMIFS(SECTOR_BASE_OIL!J$3:J$10000,SECTOR_BASE_OIL!$B$3:$B$10000,$A3,SECTOR_BASE_OIL!$C$3:$C$10000,$B3,SECTOR_BASE_OIL!$D$3:$D$10000,$C3) -> 226.12432 | I3: =SUMIFS(SECTOR_BASE_OIL!L$3:L$10000,SECTOR_BASE_OIL!$B$3:$B$10000,$A3,SECTOR_BASE_OIL!$C$3:$C$10000,$B3,SECTOR_BASE_OIL!$D$3:$D$10000,$C3) -> 247.57812
